Workbook

Sheet Setup & Dashboard
B2: CHIKO_LIFTS : THE 13-WEEK STRENGTHBENDER SYSTEM
B3: Official Periodized Strength & Peaking Protocol — Dynamic Master Workbook
B5: 1. ATHLETE MAXES & TRAINING MAX CALCULATOR | G5: CORE AUTOREGULATION & RULES
B6: Lift | C6: Current 1RM (lbs) | D6: TM Percentage | E6: Calculated TM (lbs) | F6: Rounding Rule | G6: • The 5% Drop Rule
B7: Back Squat | C7: 335 | D7: 90% | E7: =ROUND(C7*0.9/5, 0)*5 | F7: Nearest 5 lbs (90% 1RM) | G7: If the first working set of any top set is >1 RPE point harder than prescribed, or bar speed slows noticeably, DROP LOAD 5% and keep prescribed sets/reps. Never grind.
B8: Bench Press | C8: 225 | D8: 90% | E8: =ROUND(C8*0.9/5, 0)*5 | F8: Nearest 5 lbs (90% 1RM) | G8: • Training Max Concept
B9: Deadlift | C9: 410 | D9: 90% | E9: =ROUND(C9*0.9/5, 0)*5 | F9: Nearest 5 lbs (90% 1RM) | G9: All percentages are calibrated against your Training Max (TM = 90% of true 1RM), NOT your absolute 1RM. This guarantees clean bar path and injury prevention.
B10: Paused Rack Pull (mid-shin) | C10: 450 | D10: Direct Entry | E10: =C10 | F10: Independent TM / Baseline Tested W1 | G10: • RPE Scale Guide
G11: @6: 4 reps in reserve (warmup/speed) @7: 3 reps in reserve (crisp, solid) @8: 2 reps in reserve (clean effort) @8-9: 1-2 reps in reserve (near-limit) @9: 1 rep in reserve (heavy single) @10: 0 reps in reserve (true PR attempt)
G12: • Deload Protocol
G13: Weeks 5 and 10 are mandatory deloads. Resist the urge to push heavier; fatigue dissipation is required to hit peak adaptations in Weeks 6-9 and 11-13.
B16: 2. 13-WEEK PERIODIZATION MACROCYCLE ROADMAP
B17: Week | C17: Phase | D17: Strategic Objective & Role in Cycle | G17: Primary Prescription | I17: Target RPE
B18: W1 | C18: Accumulation | D18: Base building: Groove movement patterns, unilateral accessories, establish Rack Pull baseline. | G18: 4x4 @ 68-70% TM | I18: RPE 7 (Submaximal)
B19: W2 | C19: Accumulation | D19: Volume accumulation: +1 set on Squat/Bench, +3% load progression. | G19: 5x4 @ 72-73% TM | I19: RPE 7
B20: W3 | C20: Accumulation | D20: Volume peak start: Sets rise to 6x3 on Squat, 5x4 on Bench, Deadlift picks up 4th set. | G20: 6x3 @ 76-77% TM | I20: RPE 7-8
B21: W4 | C21: Accumulation Peak | D21: Block fatigue peak: Heaviest accumulation sessions before reset. Paused DL dropped to protect back. | G21: 6x3 @ 80% TM | I21: RPE 8 (Fatigue High)
B22: W5 | C22: Deload | D22: Fatigue dissipation: Deload volume and intensity to absorb training stress. | G22: 2-3x3 @ 55-60% TM | I22: RPE 6 (Recovery)
B23: W6 | C23: Intensification | D23: Shift to neural drive: Volume drops, bar intensity jumps into 80s. | G23: 5x3 @ 82-83% TM | I23: RPE 8 (Rested)
B24: W7 | C24: Intensification | D24: Doubles transition: Heavy doubles commence across all 4 lifts. | G24: 5-6x2 @ 86-87% TM | I24: RPE 8
B25: W8 | C25: Intensification | D25: Heavy doubles threshold: Competition attempt weight familiarity. | G25: 3-5x2 @ 88-90% TM | I25: RPE 8-9 (Heavy)
B26: W9 | C26: Top of Intensification | D26: Final near-max check: Controlled doubles + speed-gated optional singles. | G26: 2-4x2 @ 88-90% (+opt single) | I26: RPE 8-9 (Critical gate)
B27: W10 | C27: Deload | D27: Pre-peak reset: Flush nervous system fatigue and supercompensate before peaking. | G27: 2-3x2 @ 60-65% TM | I27: RPE 6 (Recovery)
B28: W11 | C28: Peak / Realization | D28: Heavy single realization: 90% TM single + back-off double at 82%. | G28: 1x1 @ 88-90% + back-offs | I28: RPE 8-9
... B30: W13 | C30: Testing Window | D30: PR Test Week: Single activation day followed by individual PR test days with rest separation. | G30: Openers @ 90% TM -> PRs | I30: RPE 9.5-10 (All-Out PRs)
B33: 3. PROJECTED PR TARGETS (13-WEEK ADAPTATION MODEL)
B34: Lift | C34: Current 1RM | D34: Est. Weekly Adaptation | E34: Projected Base PR | F34: Conservative Range | G34: Aggressive Range | H34: Testing Day
B35: Back Squat | C35: =C7 | D35: +0.5% / week | E35: =ROUND(C7*1.067/5, 0)*5 | F35: =ROUND(E35*0.97/5, 0)*5 | G35: =ROUND(E35*1.03/5, 0)*5 | H35: Week 13 — Day 3 (Day C)
B36: Bench Press | C36: =C8 | D36: +0.5% / week | E36: =ROUND(C8*1.067/5, 0)*5 | F36: =ROUND(E36*0.97/5, 0)*5 | G36: =ROUND(E36*1.03/5, 0)*5 | H36: Week 13 — Day 2 (Day B)
B37: Deadlift | C37: =C9 | D37: +0.5% / week | E37: =ROUND(C9*1.067/5, 0)*5 | F37: =ROUND(E37*0.97/5, 0)*5 | G37: =ROUND(E37*1.03/5, 0)*5 | H37: Week 13 — Day 4 (Day D)
B38: Rack Pull | C38: =C10 | D38: +0.5% / week | E38: =ROUND(C10*1.067/5, 0)*5 | F38: =ROUND(E38*0.97/5, 0)*5 | G38: =ROUND(E38*1.03/5, 0)*5 | H38: Week 13 — Day 5 (Day E)

Sheet Master Program (All Weeks)
A1: CHIKO_LIFTS : MASTER 13-WEEK TRAINING PROGRAM LOG
A2: All 13 Weeks, 65 Sessions & 259 Exercises — Live Dynamic Prescribed Load Formulas Linked to Setup & Dashboard TM
A3: Week | B3: Phase | C3: Day # | D3: Day Label / Focus | E3: Ex # | F3: Exercise Name | G3: Type | H3: Lift Ref | I3: Sets | J3: Reps | K3: % TM | L3: Prescribed Load (lbs) | M3: Target RPE | N3: Prescription / Coaching Notes | O3: Actual Load (lbs) | P3: Actual Reps / Notes
A4: 1 | B4: Accumulation | C4: 1 | D4: Monday — Squat | E4: 1 | F4: Back squat | G4: Main Lift | H4: SQUAT | I4: 4 | J4: 4 | K4: 0.7 | L4: =ROUND('Setup & Dashboard'!$E$7*0.7/5, 0)*5 | M4: RPE 7
A5: 1 | B5: Accumulation | C5: 1 | D5: Monday — Squat | E5: 2 | F5: Bulgarian split squat | G5: Accessory | H5: - | I5: 3 | J5: 10/leg
A6: 1 | B6: Accumulation | C6: 1 | D6: Monday — Squat | E6: 3 | F6: Seated leg curl | G6: Accessory | H6: - | I6: 3 | J6: 12
A7: 1 | B7: Accumulation | C7: 1 | D7: Monday — Squat | E7: 4 | F7: Pallof press | G7: Accessory | H7: - | I7: 3 | J7: 10/side
A8: 1 | B8: Accumulation | C8: 1 | D8: Monday — Squat | E8: 5 | F8: Standing calf raise | G8: Accessory | H8: - | I8: 3 | J8: 15
A9: 1 | B9: Accumulation | C9: 2 | D9: Tuesday — Bench | E9: 1 | F9: Bench press | G9: Main Lift | H9: BENCH | I9: 4 | J9: 4 | K9: 0.7 | L9: =ROUND('Setup & Dashboard'!$E$8*0.7/5, 0)*5 | M9: RPE 7
A10: 1 | B10: Accumulation | C10: 2 | D10: Tuesday — Bench | E10: 2 | F10: Close-grip bench | G10: Accessory | H10: - | I10: 3 | J10: 6 | M10: RPE 7
A11: 1 | B11: Accumulation | C11: 2 | D11: Tuesday — Bench | E11: 3 | F11: Incline DB press | G11: Accessory | H11: - | I11: 3 | J11: 12
A12: 1 | B12: Accumulation | C12: 2 | D12: Tuesday — Bench | E12: 4 | F12: Triceps pressdown | G12: Accessory | H12: - | I12: 3 | J12: 12
A13: 1 | B13: Accumulation | C13: 2 | D13: Tuesday — Bench | E13: 5 | F13: Face pull | G13: Accessory | H13: - | I13: 3 | J13: 15
A14: 1 | B14: Accumulation | C14: 3 | D14: Thursday — Deadlift | E14: 1 | F14: Deadlift | G14: Main Lift | H14: DEADLIFT | I14: 3 | J14: 4 | K14: 0.68 | L14: =ROUND('Setup & Dashboard'!$E$9*0.68/5, 0)*5 | M14: RPE 7
A15: 1 | B15: Accumulation | C15: 3 | D15: Thursday — Deadlift | E15: 2 | F15: Paused deadlift (mid-shin) | G15: Accessory | H15: DEADLIFT | I15: 2 | J15: 3 | K15: 0.55 | L15: =ROUND('Setup & Dashboard'!$E$9*0.55/5, 0)*5
A16: 1 | B16: Accumulation | C16: 3 | D16: Thursday — Deadlift | E16: 3 | F16: Farmer's carry | G16: Accessory | H16: - | I16: 3 | J16: 30-40m
A17: 1 | B17: Accumulation | C17: 3 | D17: Thursday — Deadlift | E17: 4 | F17: Reverse hyper | G17: Accessory | H17: - | I17: 2 | J17: 15
A18: 1 | B18: Accumulation | C18: 3 | D18: Thursday — Deadlift | E18: 5 | F18: Jefferson curl | G18: Accessory | H18: - | I18: 2 | J18: 8
A19: 1 | B19: Accumulation | C19: 4 | D19: Friday — Bench variant / upper body | E19: 1 | F19: Tempo bench (3-1-1) | G19: Main Lift | H19: BENCH | I19: 4 | J19: 4 | K19: 0.65 | L19: =ROUND('Setup & Dashboard'!$E$8*0.65/5, 0)*5 | M19: RPE 6-7
A20: 1 | B20: Accumulation | C20: 4 | D20: Friday — Bench variant / upper body | E20: 2 | F20: Chest-supported row | G20: Accessory | H20: - | I20: 4 | J20: 10
A21: 1 | B21: Accumulation | C21: 4 | D21: Friday — Bench variant / upper body | E21: 3 | F21: Lat pulldown | G21: Accessory | H21: - | I21: 3 | J21: 12
A22: 1 | B22: Accumulation | C22: 4 | D22: Friday — Bench variant / upper body | E22: 4 | F22: Lateral raise | G22: Accessory | H22: - | I22: 3 | J22: 15
A23: 1 | B23: Accumulation | C23: 4 | D23: Friday — Bench variant / upper body | E23: 5 | F23: Curl | G23: Accessory | H23: - | I23: 3 | J23: 12
A24: 1 | B24: Accumulation | C24: 4 | D24: Friday — Bench variant / upper body | E24: 6 | F24: Pallof press | G24: Accessory | H24: - | I24: 3 | J24: 10/side
A25: 1 | B25: Accumulation | C25: 5 | D25: Saturday — Squat variant + Rack Pull | E25: 1 | F25: Paused squat | G25: Main Lift | H25: SQUAT | I25: 3 | J25: 3 | K25: 0.7 | L25: =ROUND('Setup & Dashboard'!$E$7*0.7/5, 0)*5 | M25: RPE 7
A26: 1 | B26: Accumulation | C26: 5 | D26: Saturday — Squat variant + Rack Pull | E26: 2 | F26: Rack pull baseline test | G26: Main Lift | H26: RACKPULL | I26: 1 | J26: 1 | N26: Bar x5, 40%x5, 55%x3, 70%x2, 80%x1, work up to clean top set @ RPE 8
A27: 1 | B27: Accumulation | C27: 5 | D27: Saturday — Squat variant + Rack Pull | E27: 3 | F27: Reverse hyper | G27: Accessory | H27: - | I27: 2 | J27: 12
A28: 1 | B28: Accumulation | C28: 5 | D28: Saturday — Squat variant + Rack Pull | E28: 4 | F28: GHR or Nordic curl | G28: Accessory | H28: - | I28: 3 | J28: 8
A29: 1 | B29: Accumulation | C29: 5 | D29: Saturday — Squat variant + Rack Pull | E29: 5 | F29: Jefferson curl | G29: Accessory | H29: - | I29: 1 | J29: 8
A30: 2 | B30: Accumulation | C30: 1 | D30: Monday — Squat | E30: 1 | F30: Back squat | G30: Main Lift | H30: SQUAT | I30: 5 | J30: 4 | K30: 0.73 | L30: =ROUND('Setup & Dashboard'!$E$7*0.73/5, 0)*5 | M30: RPE 7
A31: 2 | B31: Accumulation | C31: 1 | D31: Monday — Squat | E31: 2 | F31: Bulgarian split squat | G31: Accessory | H31: - | I31: 3 | J31: 10/leg
A32: 2 | B32: Accumulation | C32: 1 | D32: Monday — Squat | E32: 3 | F32: Leg curl | G32: Accessory | H32: - | I32: 3 | J32: 12
A33: 2 | B33: Accumulation | C33: 1 | D33: Monday — Squat | E33: 4 | F33: Copenhagen plank | G33: Accessory | H33: - | I33: 3 | J33: 20sec/side
A34: 2 | B34: Accumulation | C34: 2 | D34: Tuesday — Bench | E34: 1 | F34: Bench press | G34: Main Lift | H34: BENCH | I34: 5 | J34: 4 | K34: 0.73 | L34: =ROUND('Setup & Dashboard'!$E$8*0.73/5, 0)*5 | M34: RPE 7
A35: 2 | B35: Accumulation | C35: 2 | D35: Tuesday — Bench | E35: 2 | F35: Close-grip bench | G35: Accessory | H35: - | I35: 3 | J35: 6
A36: 2 | B36: Accumulation | C36: 2 | D36: Tuesday — Bench | E36: 3 | F36: Incline DB press | G36: Accessory | H36: - | I36: 3 | J36: 12
A37: 2 | B37: Accumulation | C37: 2 | D37: Tuesday — Bench | E37: 4 | F37: Triceps pressdown | G37: Accessory | H37: - | I37: 3 | J37: 12
A38: 2 | B38: Accumulation | C38: 2 | D38: Tuesday — Bench | E38: 5 | F38: Face pull | G38: Accessory | H38: - | I38: 3 | J38: 15
A39: 2 | B39: Accumulation | C39: 3 | D39: Thursday — Deadlift | E39: 1 | F39: Deadlift | G39: Main Lift | H39: DEADLIFT | I39: 3 | J39: 4 | K39: 0.72 | L39: =ROUND('Setup & Dashboard'!$E$9*0.72/5, 0)*5 | M39: RPE 7
A40: 2 | B40: Accumulation | C40: 3 | D40: Thursday — Deadlift | E40: 2 | F40: Paused deadlift | G40: Accessory | H40: DEADLIFT | I40: 2 | J40: 3 | K40: 0.58 | L40: =ROUND('Setup & Dashboard'!$E$9*0.58/5, 0)*5
...

Sheet Block 1 (W1-5)
A1: CHIKO_LIFTS : BLOCK 1 (W1-5) (WEEKS 1–5)
A2: Accumulation Base (W1-3) ➔ Volume Peak (W4) ➔ Deload (W5)
A4: WEEK 1 — ACCUMULATION
A5: Day 1 : Monday — Squat
A6: 💡 Coaching Rationale: Opens the cycle at 70% TM for 4x4, a volume/intensity combo you should be able to execute well short of failure. The job this week isn't to push RPE, it's to groove the pattern under load and establish a baseline your body can build on. Split squats and leg curls target the unilateral stability and hamstring strength that heavier squats will demand later.
A7: # | B7: Exercise | C7: Type | D7: Sets | E7: Reps | F7: % TM | G7: Prescribed Weight | H7: Target RPE | I7: Prescription Notes | J7: Actual Weight | K7: Actual Reps | L7: Done?
A8: 1 | B8: Back squat | C8: MAIN | D8: 4 | E8: 4 | F8: 0.7 | G8: =ROUND('Setup & Dashboard'!$E$7*0.7/5, 0)*5 | H8: RPE 7
A9: 2 | B9: Bulgarian split squat | C9: Acc | D9: 3 | E9: 10/leg
A10: 3 | B10: Seated leg curl | C10: Acc | D10: 3 | E10: 12
A11: 4 | B11: Pallof press | C11: Acc | D11: 3 | E11: 10/side
A12: 5 | B12: Standing calf raise | C12: Acc | D12: 3 | E12: 15
A14: Day 2 : Tuesday — Bench
A15: 💡 Coaching Rationale: Mirrors Day 1's approach at the same 70% TM. Close-grip bench and triceps work start building the lockout strength you won't need yet but will in Weeks 8-12. Face pulls are prophylactic — they keep the rear delts/rotator cuff balanced against all the pressing volume before it accumulates.
A16: # | B16: Exercise | C16: Type | D16: Sets | E16: Reps | F16: % TM | G16: Prescribed Weight | H16: Target RPE | I16: Prescription Notes | J16: Actual Weight | K16: Actual Reps | L16: Done?
A17: 1 | B17: Bench press | C17: MAIN | D17: 4 | E17: 4 | F17: 0.7 | G17: =ROUND('Setup & Dashboard'!$E$8*0.7/5, 0)*5 | H17: RPE 7
A18: 2 | B18: Close-grip bench | C18: Acc | D18: 3 | E18: 6 | H18: RPE 7
A19: 3 | B19: Incline DB press | C19: Acc | D19: 3 | E19: 12
A20: 4 | B20: Triceps pressdown | C20: Acc | D20: 3 | E20: 12
A21: 5 | B21: Face pull | C21: Acc | D21: 3 | E21: 15
A23: Day 3 : Thursday — Deadlift
A24: 💡 Coaching Rationale: Deliberately the lightest relative-intensity day of the week (68% TM) because deadlift is the most fatigue-expensive lift you do — a 'moderate' deadlift session costs more recovery than a moderate squat or bench session. Paused deadlift and farmer's carries add extra pulling volume without loading the bar as heavy as the main lift, which is how you build deadlift work capacity without digging a hole this early.
A25: # | B25: Exercise | C25: Type | D25: Sets | E25: Reps | F25: % TM | G25: Prescribed Weight | H25: Target RPE | I25: Prescription Notes | J25: Actual Weight | K25: Actual Reps | L25: Done?
A26: 1 | B26: Deadlift | C26: MAIN | D26: 3 | E26: 4 | F26: 0.68 | G26: =ROUND('Setup & Dashboard'!$E$9*0.68/5, 0)*5 | H26: RPE 7
A27: 2 | B27: Paused deadlift (mid-shin) | C27: Acc | D27: 2 | E27: 3 | F27: 0.55 | G27: =ROUND('Setup & Dashboard'!$E$9*0.55/5, 0)*5
A28: 3 | B28: Farmer's carry | C28: Acc | D28: 3 | E28: 30-40m
A29: 4 | B29: Reverse hyper | C29: Acc | D29: 2 | E29: 15
A30: 5 | B30: Jefferson curl | C30: Acc | D30: 2 | E30: 8
A32: Day 4 : Friday — Bench variant / upper body
A33: 💡 Coaching Rationale: This is a bench frequency day, not a second heavy bench day — the 3-1-1 tempo at 65% keeps intensity low while reinforcing bar path and control. The real work here is the back: rows and pulldowns build the upper-back tightness that stabilizes heavy bench press later, and this is the best week to start that development, before fatigue accumulates.
A34: # | B34: Exercise | C34: Type | D34: Sets | E34: Reps | F34: % TM | G34: Prescribed Weight | H34: Target RPE | I34: Prescription Notes | J34: Actual Weight | K34: Actual Reps | L34: Done?
A35: 1 | B35: Tempo bench (3-1-1) | C35: MAIN | D35: 4 | E35: 4 | F35: 0.65 | G35: =ROUND('Setup & Dashboard'!$E$8*0.65/5, 0)*5 | H35: RPE 6-7
A36: 2 | B36: Chest-supported row | C36: Acc | D36: 4 | E36: 10
A37: 3 | B37: Lat pulldown | C37: Acc | D37: 3 | E37: 12
A38: 4 | B38: Lateral raise | C38: Acc | D38: 3 | E38: 15
A39: 5 | B39: Curl | C39: Acc | D39: 3 | E39: 12
A40: 6 | B40: Pallof press | C40: Acc | D40: 3 | E40: 10/side
A42: Day 5 : Saturday — Squat variant + Rack Pull
A43: 💡 Coaching Rationale: Paused squat adds positional strength work for the bottom of the squat. The rack pull test (working up to a clean RPE 8 top set) exists to establish your actual starting point for rack pull TM — everything for the next 12 weeks on that lift is calibrated off today's number, so treat it seriously but don't grind past RPE 8.
A44: # | B44: Exercise | C44: Type | D44: Sets | E44: Reps | F44: % TM | G44: Prescribed Weight | H44: Target RPE | I44: Prescription Notes | J44: Actual Weight | K44: Actual Reps | L44: Done?
A45: 1 | B45: Paused squat | C45: MAIN | D45: 3 | E45: 3 | F45: 0.7 | G45: =ROUND('Setup & Dashboard'!$E$7*0.7/5, 0)*5 | H45: RPE 7
...

Sheet Block 2 (W6-10)
A1: CHIKO_LIFTS : BLOCK 2 (W6-10) (WEEKS 6–10)
A2: Intensification Doubles (W6-8) ➔ Top of Intensification (W9) ➔ Deload (W10)
A4: WEEK 6 — INTENSIFICATION
A5: Day 1 : Monday — Squat
A6: 💡 Coaching Rationale: Sets drop back to 5, reps stay at 3, but intensity jumps to 83% — the shift from accumulation logic (more volume, moderate intensity) to intensification logic (less volume, higher intensity) starts here. RPE 8 should feel similar to Week 4's RPE 8, even though the % is higher, because you're rested.
A7: # | B7: Exercise | C7: Type | D7: Sets | E7: Reps | F7: % TM | G7: Prescribed Weight | H7: Target RPE | I7: Prescription Notes | J7: Actual Weight | K7: Actual Reps | L7: Done?
A8: 1 | B8: Squat | C8: MAIN | D8: 5 | E8: 3 | F8: 0.83 | G8: =ROUND('Setup & Dashboard'!$E$7*0.83/5, 0)*5 | H8: RPE 8
A9: 2 | B9: Bulgarian split squat | C9: Acc | D9: 3 | E9: 8
A10: 3 | B10: Leg curl | C10: Acc | D10: 3 | E10: 10
A11: 4 | B11: Copenhagen plank | C11: Acc | D11: 3 | E11: 20sec/side
A13: Day 2 : Tuesday — Bench
A14: 💡 Coaching Rationale: Same shift — 5x3 @ 83%, RPE 8.
A15: # | B15: Exercise | C15: Type | D15: Sets | E15: Reps | F15: % TM | G15: Prescribed Weight | H15: Target RPE | I15: Prescription Notes | J15: Actual Weight | K15: Actual Reps | L15: Done?
A16: 1 | B16: Bench | C16: MAIN | D16: 5 | E16: 3 | F16: 0.83 | G16: =ROUND('Setup & Dashboard'!$E$8*0.83/5, 0)*5 | H16: RPE 8
A17: 2 | B17: Close-grip bench | C17: Acc | D17: 3 | E17: 5
A18: 3 | B18: Incline DB press | C18: Acc | D18: 3 | E18: 8-10
A19: 4 | B19: Triceps pressdown | C19: Acc | D19: 3 | E19: 12
A20: 5 | B20: Face pull | C20: Acc | D20: 3 | E20: 15
A22: Day 3 : Thursday — Deadlift
A23: 💡 Coaching Rationale: 3x3 @ 82% — deadlift volume actually drops (from 4 sets to 3) as intensity climbs, protecting recovery as the numbers on the bar get heavier.
A24: # | B24: Exercise | C24: Type | D24: Sets | E24: Reps | F24: % TM | G24: Prescribed Weight | H24: Target RPE | I24: Prescription Notes | J24: Actual Weight | K24: Actual Reps | L24: Done?
A25: 1 | B25: Deadlift | C25: MAIN | D25: 3 | E25: 3 | F25: 0.82 | G25: =ROUND('Setup & Dashboard'!$E$9*0.82/5, 0)*5 | H25: RPE 8
A26: 2 | B26: Reverse hyper | C26: Acc | D26: 2 | E26: 12
A27: 3 | B27: Jefferson curl | C27: Acc | D27: 2 | E27: 8
A29: Day 4 : Friday — Bench variant / upper body
A30: 💡 Coaching Rationale: Spoto press intensity ticks up modestly (65%) but stays a genuinely sub-maximal accessory day — this session's job is still support work, not pushing a new intensity high.
A31: # | B31: Exercise | C31: Type | D31: Sets | E31: Reps | F31: % TM | G31: Prescribed Weight | H31: Target RPE | I31: Prescription Notes | J31: Actual Weight | K31: Actual Reps | L31: Done?
A32: 1 | B32: Spoto press | C32: MAIN | D32: 4 | E32: 3 | F32: 0.65 | G32: =ROUND('Setup & Dashboard'!$E$8*0.65/5, 0)*5 | H32: RPE 7
A33: 2 | B33: Chest-supported row | C33: Acc | D33: 4 | E33: 8
A34: 3 | B34: Lat pulldown | C34: Acc | D34: 3 | E34: 10
A35: 4 | B35: Lateral raise | C35: Acc | D35: 3 | E35: 15
A36: 5 | B36: Curl | C36: Acc | D36: 3 | E36: 10-12
A37: 6 | B37: Pallof press | C37: Acc | D37: 3 | E37: 10/side
A39: Day 5 : Saturday — Squat variant + Rack Pull
A40: 💡 Coaching Rationale: Rack pull moves to 4x3 @ 80%, matching the intensification shift seen everywhere else this week — fewer sets, heavier load.
A41: # | B41: Exercise | C41: Type | D41: Sets | E41: Reps | F41: % TM | G41: Prescribed Weight | H41: Target RPE | I41: Prescription Notes | J41: Actual Weight | K41: Actual Reps | L41: Done?
A42: 1 | B42: High bar squat | C42: MAIN | D42: 3 | E42: 4 | F42: 0.65 | G42: =ROUND('Setup & Dashboard'!$E$7*0.65/5, 0)*5 | H42: RPE 7
A43: 2 | B43: Rack pull | C43: MAIN | D43: 4 | E43: 3 | F43: 0.8 | G43: =ROUND('Setup & Dashboard'!$E$10*0.8/5, 0)*5 | H43: RPE 8
A44: 3 | B44: Reverse hyper | C44: Acc | D44: 2 | E44: 12
A45: 4 | B45: GHR or Nordic curl | C45: Acc | D45: 3 | E45: 8
...

Sheet Block 3 (W11-13)
A1: CHIKO_LIFTS : BLOCK 3 (W11-13) (WEEKS 11–13)
A2: Peak / Realization (W11) ➔ FINAL FORM Taper (W12) ➔ Testing Window PRs (W13)
A4: WEEK 11 — PEAK / REALIZATION
A5: Day 1 : Monday — Squat
A6: 💡 Coaching Rationale: A true heavy single at 90% TM, RPE 8-9 — deliberately lower than the original program's 92-93% call, because this is now two near-max exposures away from your actual PR attempt, not one. The back-off doubles at 82% add a small amount of extra quality volume without turning this into another intensification-style session.
A7: # | B7: Exercise | C7: Type | D7: Sets | E7: Reps | F7: % TM | G7: Prescribed Weight | H7: Target RPE | I7: Prescription Notes | J7: Actual Weight | K7: Actual Reps | L7: Done?
A8: 1 | B8: Squat | C8: MAIN | D8: 1 | E8: 1 | F8: 0.9 | G8: =ROUND('Setup & Dashboard'!$E$7*0.9/5, 0)*5 | H8: RPE 8-9 | I8: then 2x1 @ 82% TM
A9: 2 | B9: Copenhagen plank | C9: Acc | D9: 2 | E9: 15sec/side
A10: 3 | B10: Pallof press | C10: Acc | D10: 2 | E10: 8/side
A12: Day 2 : Tuesday — Bench
A13: 💡 Coaching Rationale: Same structure and same reasoning — 90% single, back-off doubles at 82%.
A14: # | B14: Exercise | C14: Type | D14: Sets | E14: Reps | F14: % TM | G14: Prescribed Weight | H14: Target RPE | I14: Prescription Notes | J14: Actual Weight | K14: Actual Reps | L14: Done?
A15: 1 | B15: Bench | C15: MAIN | D15: 1 | E15: 1 | F15: 0.9 | G15: =ROUND('Setup & Dashboard'!$E$8*0.9/5, 0)*5 | H15: RPE 8-9 | I15: then 2x1 @ 82% TM
A16: 2 | B16: Close-grip bench | C16: Acc | D16: 2 | E16: 3
A17: 3 | B17: Face pull | C17: Acc | D17: 2 | E17: 15
A19: Day 3 : Thursday — Deadlift
A20: 💡 Coaching Rationale: A single heavy attempt at 88% and nothing else beyond reverse hyper — deadlift gets the least additional work of any lift this week because it has the least recovery runway left before test week.
A21: # | B21: Exercise | C21: Type | D21: Sets | E21: Reps | F21: % TM | G21: Prescribed Weight | H21: Target RPE | I21: Prescription Notes | J21: Actual Weight | K21: Actual Reps | L21: Done?
A22: 1 | B22: Deadlift | C22: MAIN | D22: 1 | E22: 1 | F22: 0.88 | G22: =ROUND('Setup & Dashboard'!$E$9*0.88/5, 0)*5 | H22: RPE 8-9
A23: 2 | B23: Reverse hyper | C23: Acc | D23: 2 | E23: 10
A25: Day 4 : Friday — Bench variant / upper body
A26: 💡 Coaching Rationale: Lower intensity (75%) than Week 9's version of this session — as you get closer to testing, every non-peak day should be getting easier, not staying flat.
A27: # | B27: Exercise | C27: Type | D27: Sets | E27: Reps | F27: % TM | G27: Prescribed Weight | H27: Target RPE | I27: Prescription Notes | J27: Actual Weight | K27: Actual Reps | L27: Done?
A28: 1 | B28: Competition-style bench | C28: MAIN | D28: 2 | E28: 2 | F28: 0.75 | G28: =ROUND('Setup & Dashboard'!$E$8*0.75/5, 0)*5 | H28: RPE 7
A29: 2 | B29: Chest-supported row | C29: Acc | D29: 2 | E29: 8
A30: 3 | B30: Lat pulldown | C30: Acc | D30: 2 | E30: 8-10
A31: 4 | B31: Lateral raise | C31: Acc | D31: 2 | E31: 12-15
A33: Day 5 : Saturday — Squat variant + Rack Pull
A34: 💡 Coaching Rationale: Rack pull's 'heavy double, then stop' prescription at 87% (down from the original 90%) is the same taper logic applied to the fourth lift — protect the number you're chasing in Week 13 by not chasing a smaller number too close to it.
A35: # | B35: Exercise | C35: Type | D35: Sets | E35: Reps | F35: % TM | G35: Prescribed Weight | H35: Target RPE | I35: Prescription Notes | J35: Actual Weight | K35: Actual Reps | L35: Done?
A36: 1 | B36: Paused squat | C36: MAIN | D36: 2 | E36: 2 | F36: 0.75 | G36: =ROUND('Setup & Dashboard'!$E$7*0.75/5, 0)*5 | H36: RPE 7
A37: 2 | B37: Rack pull | C37: MAIN | D37: 1 | E37: 2 | F37: 0.87 | G37: =ROUND('Setup & Dashboard'!$E$10*0.87/5, 0)*5 | I37: 1 heavy double, then stop
A38: 3 | B38: Reverse hyper | C38: Acc | D38: 1 | E38: 10
A41: WEEK 12 — FINAL FORM (TAPER)
A42: Day 1 : Monday — Squat
A43: 💡 Coaching Rationale: 3x1 @ 85%, RPE 7-8, explicitly framed as 'crisp reps only, stop if speed drops.' This is the core taper principle: intensity stays moderate-high so the nervous system stays primed, but nothing here is a new max effort. The original program had a 95% single scheduled this week — the single biggest risk in the whole 13 weeks — and it's removed entirely.
A44: # | B44: Exercise | C44: Type | D44: Sets | E44: Reps | F44: % TM | G44: Prescribed Weight | H44: Target RPE | I44: Prescription Notes | J44: Actual Weight | K44: Actual Reps | L44: Done?
A45: 1 | B45: Squat | C45: MAIN | D45: 3 | E45: 1 | F45: 0.85 | G45: =ROUND('Setup & Dashboard'!$E$7*0.85/5, 0)*5 | H45: RPE 7-8 | I45: crisp reps only, stop if speed drops
A46: 2 | B46: Pallof press | C46: Acc | D46: 1 | E46: 8/side
A48: Day 2 : Tuesday — Bench
...

Sheet Week 13 PR Testing Plan
A1: CHIKO_LIFTS : WEEK 13 PR TESTING WINDOW & ATTEMPT SELECTOR
A2: Strategic 5-Day Testing Architecture — Structured Rest Intervals & Calculated 3-Attempt Progression
A4: TESTING RULES & ATTEMPT STRATEGY
A5: • Separation Rule: Never test multiple max lifts on consecutive days. Bench tested first (fastest recovery), followed by 1 rest day before Squat, 2 rest days before Deadlift, and 2 rest days before Rack Pull. • Opener (~90% TM): Must be a weight you can triple on your worst day. Serves as confidence builder and ensures a solid number on the board. • 2nd Attempt (~100% TM / previous 1RM): A smooth, aggressive attempt to equal or slightly top your old best. • 3rd Attempt (PR Target): Based on how fast Attempt 2 moved. Jump 5-15 lbs to set your brand new all-time Personal Record.
A8: Test Day | B8: Lift Scheduled | C8: Rest Prior | D8: Opener (90% TM) | E8: Attempt 2 Target | F8: Attempt 3 (PR Target) | G8: Warm-up Primer | H8: Plate Loading (Opener) | I8: Coaching Strategy & Notes | J8: Actual PR Result
A9: Day 1 (Day A) | B9: Light Activation (Squat + Bench) | C9: Follows Taper | D9: =ROUND('Setup & Dashboard'!$E$7*0.5/5, 0)*5 | E9: =ROUND('Setup & Dashboard'!$E$8*0.5/5, 0)*5 | F9: - | G9: Bar x 10, 50% 2x3 | H9: N/A | I9: Neural priming only. Move crisp and fast. Zero fatigue. | J9: Ready
A10: Day 2 (Day B) | B10: Bench Press PR | C10: 1 Rest Day | D10: =ROUND('Setup & Dashboard'!$E$8*0.9/5, 0)*5 | E10: =ROUND('Setup & Dashboard'!$C$8/5, 0)*5 | F10: =ROUND('Setup & Dashboard'!$C$8*1.05/5, 0)*5 | G10: 45x10, 95x5, 135x3, 185x1 | H10: 45 + plates / side | I10: Bench recovers fastest. Hit opener, take small jump, then attack PR.
A11: Day 3 (Day C) | B11: Back Squat PR | C11: 1 Rest Day | D11: =ROUND('Setup & Dashboard'!$E$7*0.9/5, 0)*5 | E11: =ROUND('Setup & Dashboard'!$C$7/5, 0)*5 | F11: =ROUND('Setup & Dashboard'!$C$7*1.05/5, 0)*5 | G11: 45x10, 135x5, 225x3, 275x1 | H11: 45 + plates / side | I11: Opener will feel light if taper was respected. Stay tight in hole.
A12: Day 4 (Day D) | B12: Deadlift PR | C12: 2 Full Rest Days | D12: =ROUND('Setup & Dashboard'!$E$9*0.9/5, 0)*5 | E12: =ROUND('Setup & Dashboard'!$C$9/5, 0)*5 | F12: =ROUND('Setup & Dashboard'!$C$9*1.05/5, 0)*5 | G12: 135x5, 225x3, 315x1, 350x1 | H12: 45 + plates / side | I12: Two full rest days pay down spinal fatigue. Lock lats, push floor away.
A13: Day 5 (Day E) | B13: Rack Pull PR | C13: 2 Full Rest Days | D13: =ROUND('Setup & Dashboard'!$E$10*0.9/5, 0)*5 | E13: =ROUND('Setup & Dashboard'!$E$10*1.03/5, 0)*5 | F13: =ROUND('Setup & Dashboard'!$E$10*1.06/5, 0)*5 | G13: 135x5, 225x3, 315x2, 405x1 | H13: 45 + plates / side | I13: Separated by 2 full rest days from DL. Test mid-shin starting strength.

Sheet Coaching Guide (65 Sessions)
A1: CHIKO_LIFTS : COMPLETE COACHING COMPENDIUM & SESSION RATIONALE
A2: The Biomechanical & Periodization Logic Behind Every Single Day of the 13-Week System
A3: Week | B3: Phase | C3: Day # | D3: Day Label / Focus | E3: Primary Lifts Programmed | F3: Session Fatigue Profile | G3: Detailed Coaching Rationale & Programming Architecture
A4: 1 | B4: Accumulation | C4: 1 | D4: Monday — Squat | E4: Back squat | F4: Moderate (Systemic Loading) | G4: Opens the cycle at 70% TM for 4x4, a volume/intensity combo you should be able to execute well short of failure. The job this week isn't to push RPE, it's to groove the pattern under load and establish a baseline your body can build on. Split squats and leg curls target the unilateral stability and hamstring strength that heavier squats will demand later.
A5: 1 | B5: Accumulation | C5: 2 | D5: Tuesday — Bench | E5: Bench press | F5: Moderate (Systemic Loading) | G5: Mirrors Day 1's approach at the same 70% TM. Close-grip bench and triceps work start building the lockout strength you won't need yet but will in Weeks 8-12. Face pulls are prophylactic — they keep the rear delts/rotator cuff balanced against all the pressing volume before it accumulates.
A6: 1 | B6: Accumulation | C6: 3 | D6: Thursday — Deadlift | E6: Deadlift | F6: Moderate (Systemic Loading) | G6: Deliberately the lightest relative-intensity day of the week (68% TM) because deadlift is the most fatigue-expensive lift you do — a 'moderate' deadlift session costs more recovery than a moderate squat or bench session. Paused deadlift and farmer's carries add extra pulling volume without loading the bar as heavy as the main lift, which is how you build deadlift work capacity without digging a hole this early.
A7: 1 | B7: Accumulation | C7: 4 | D7: Friday — Bench variant / upper body | E7: Tempo bench (3-1-1) | F7: Moderate (Systemic Loading) | G7: This is a bench frequency day, not a second heavy bench day — the 3-1-1 tempo at 65% keeps intensity low while reinforcing bar path and control. The real work here is the back: rows and pulldowns build the upper-back tightness that stabilizes heavy bench press later, and this is the best week to start that development, before fatigue accumulates.
A8: 1 | B8: Accumulation | C8: 5 | D8: Saturday — Squat variant + Rack Pull | E8: Paused squat / Rack pull baseline test | F8: Moderate (Systemic Loading) | G8: Paused squat adds positional strength work for the bottom of the squat. The rack pull test (working up to a clean RPE 8 top set) exists to establish your actual starting point for rack pull TM — everything for the next 12 weeks on that lift is calibrated off today's number, so treat it seriously but don't grind past RPE 8.
A9: 2 | B9: Accumulation | C9: 1 | D9: Monday — Squat | E9: Back squat | F9: Moderate (Systemic Loading) | G9: Same structure as Week 1, one set added (5x4) and intensity up 3% (73%). This is the standard accumulation progression — small, repeatable jumps that let you accumulate quality reps without a spike in fatigue.
A10: 2 | B10: Accumulation | C10: 2 | D10: Tuesday — Bench | E10: Bench press | F10: Moderate (Systemic Loading) | G10: Same logic as Day 1 — one more set, 3% more load. You should still be finishing sets with 2-3 reps in reserve.
A11: 2 | B11: Accumulation | C11: 3 | D11: Thursday — Deadlift | E11: Deadlift | F11: Moderate (Systemic Loading) | G11: Load moves to 72%, still 3 sets — deadlift is the one lift that doesn't get a set added here, because the fatigue cost per set is steep enough that stacking volume too fast is how deadlift-specific overreach happens. Paused deadlift intensity ticks up slightly to keep pace.
A12: 2 | B12: Accumulation | C12: 4 | D12: Friday — Bench variant / upper body | E12: Paused bench | F12: Moderate (Systemic Loading) | G12: Paused bench replaces tempo bench as the frequency movement — it's a different stimulus (dead-stop strength off the chest) at the same intensity, which keeps this day from getting stale while still serving as a lower-stress second bench touch.
A13: 2 | B13: Accumulation | C13: 5 | D13: Saturday — Squat variant + Rack Pull | E13: High bar squat / Rack pull | F13: Moderate (Systemic Loading) | G13: High bar squat at low intensity (65%) is a variation day — more quad emphasis, more upright torso, which builds a different piece of the squat than the low-bar/competition-style work on Day 1. Rack pull moves from a one-off test to real programmed work: 4x4 at 70%, mirroring the same volume approach as squat and bench.
A14: 3 | B14: Accumulation | C14: 1 | D14: Monday — Squat | E14: Squat | F14: Moderate (Systemic Loading) | G14: Sets climb to 6x3 while reps per set drop — this is the volume peak of the block starting to show. Total load lifted keeps rising even though reps-per-set fall, which is how accumulation blocks build work capacity without needing RPE to spike.
A15: 3 | B15: Accumulation | C15: 2 | D15: Tuesday — Bench | E15: Bench | F15: Moderate (Systemic Loading) | G15: Same pattern as squat — more sets, fewer reps, intensity now at 76%. RPE creeping to 7-8 is expected and fine; this is still sub-maximal work.
... A68: 13 | B68: Testing Window | C68: 5 | D68: Day E — Rack Pull PR (After 2 Rest Days) | E68: Rack Pull Opener | F68: Max Effort (Attempt Day) | G68: The last attempt in the program, and now separated from deadlift by two rest days instead of sitting on the very next training day as in the original layout. This single change — spacing the two pulling lifts apart — is the difference between rack pull's number reflecting your actual strength versus reflecting how tired your back was three days into a testing block.

Sheet Plate & Warm-up Reference
A1: CHIKO_LIFTS : BARBELL PLATE LOADING & WARM-UP PROTOCOLS
A2: Standard Olympic Bar (45 lbs) Plate Pair Configurations & Algorithmic Warm-up Ladders
A4: A. BARBELL PLATE LOADING REFERENCE (PER SIDE ON 45 LB BAR) | H4: B. APP WARM-UP LADDER PROTOCOL
A5: Total Weight (lbs) | B5: Weight Per Side (lbs) | C5: 45 lb Plates | D5: 35 / 25 lb Plates | E5: 10 / 5 / 2.5 lb Plates | F5: Full Loading Summary | H5: Step | I5: Prescription Target | J5: Rep Scheme
A6: 95 | B6: 25 | C6: - | D6: 1x 25 | E6: - | F6: 1x25 / side | H6: Step 1: Empty Bar | I6: 45 lbs | J6: 10 reps (Bar groove)
A7: 115 | B7: 35 | C7: - | D7: 1x 35 | E7: - | F7: 1x35 / side | H7: Step 2: 1st Load Jump | I7: Bench: 95-135 lbs / Squat & DL: 135-185 lbs | J7: 5 reps (Rhythm)
A8: 135 | B8: 45 | C8: 1 plate(s) | D8: - | E8: - | F8: 1x45 / side | H8: Step 3: Moderate Load | I8: 40% - 60% of Target Working Weight | J8: 5 reps (Speed focus)
A9: 155 | B9: 55 | C9: 1 plate(s) | D9: - | E9: 1x 10 | F9: 1x45 + 1x10 / side | H9: Step 4: Potentiation | I9: 75% - 80% of Target Working Weight | J9: 3 reps (Zero grind)
A10: 175 | B10: 65 | C10: 1 plate(s) | D10: - | E10: 2x 10 | F10: 1x45 + 2x10 / side | H10: Step 5: Final Acclimation | I10: 90% of Target Working Weight (if heavy) | J10: 1 rep (Crisp primer)
A11: 185 | B11: 70 | C11: 1 plate(s) | D11: 1x 25 | E11: - | F11: 1x45 + 1x25 / side | H11: Working Sets | I11: Target Programmed Weight & RPE | J11: Prescribed Sets x Reps
A12: 205 | B12: 80 | C12: 1 plate(s) | D12: 1x 35 | E12: - | F12: 1x45 + 1x35 / side
A13: 215 | B13: 85 | C13: 1 plate(s) | D13: 1x 35 | E13: 1x 5 | F13: 1x45 + 1x35 + 1x5 / side | H13: COACHING TIP: WARM-UP FATIGUE DISCIPLINE
A14: 225 | B14: 90 | C14: 2 plate(s) | D14: - | E14: - | F14: 2x45 / side | H14: • Warm-ups exist to grease the groove, potentiate high-threshold motor units, and check joint readiness. • Never take warm-ups to failure or accumulate unnecessary lactic acid. • Keep rest periods brief on early steps (60s), extending to 2-3 minutes before the final primer single and first working set. • If bar speed slows during warm-ups, heed the 5% autoregulation drop rule on working sets.
A15: 245 | B15: 100 | C15: 2 plate(s) | D15: - | E15: 1x 10 | F15: 2x45 + 1x10 / side
A16: 265 | B16: 110 | C16: 2 plate(s) | D16: - | E16: 2x 10 | F16: 2x45 + 2x10 / side
A17: 275 | B17: 115 | C17: 2 plate(s) | D17: 1x 25 | E17: - | F17: 2x45 + 1x25 / side
A18: 295 | B18: 125 | C18: 2 plate(s) | D18: 1x 35 | E18: - | F18: 2x45 + 1x35 / side
A19: 305 | B19: 130 | C19: 2 plate(s) | D19: 1x 35 | E19: 1x 5 | F19: 2x45 + 1x35 + 1x5 / side
A20: 315 | B20: 135 | C20: 3 plate(s) | D20: - | E20: - | F20: 3x45 / side
A21: 335 | B21: 145 | C21: 3 plate(s) | D21: - | E21: 1x 10 | F21: 3x45 + 1x10 / side
A22: 355 | B22: 155 | C22: 3 plate(s) | D22: - | E22: 2x 10 | F22: 3x45 + 2x10 / side
A23: 365 | B23: 160 | C23: 3 plate(s) | D23: 1x 25 | E23: - | F23: 3x45 + 1x25 / side
A24: 385 | B24: 170 | C24: 3 plate(s) | D24: 1x 35 | E24: - | F24: 3x45 + 1x35 / side
A25: 405 | B25: 180 | C25: 4 plate(s) | D25: - | E25: - | F25: 4x45 / side
A26: 425 | B26: 190 | C26: 4 plate(s) | D26: - | E26: 1x 10 | F26: 4x45 + 1x10 / side
... A35: 585 | B35: 270 | C35: 6 plate(s) | D35: - | E35: - | F35: 6x45 / side
