Workbook

Sheet Setup & Dashboard
B2: CHIKO_LIFTS : THE 13-WEEK STRENGTHBENDER SYSTEM
B3: Official Periodized Strength & Peaking Protocol — Dynamic Master Workbook (Program 2.0)
B5: 1. ATHLETE 1RM MAXES (ENTER YOUR NUMBERS) | G5: PROGRAM RULES & AUTOREGULATION
B6: Lift | C6: Your 1RM Max (lbs) | D6: Program Calculation Basis | E6: Rounding Rule | G6: • The 5% Drop Rule
B7: Back Squat | C7: 325 | D7: Direct 1RM (100% Base) | E7: All % loads round to nearest 5 lbs: =ROUND(C7*pct/5, 0)*5 | G7: If the first working set of any top set feels >1 RPE point harder than prescribed, or bar speed visibly drops, DROP THE LOAD 5% and complete prescribed sets/reps. Never grind.
B8: Bench Press | C8: 225 | D8: Direct 1RM (100% Base) | E8: All % loads round to nearest 5 lbs: =ROUND(C8*pct/5, 0)*5 | G8: • Direct 1RM Basis
B9: Deadlift | C9: 405 | D9: Direct 1RM (100% Base) | E9: All % loads round to nearest 5 lbs: =ROUND(C9*pct/5, 0)*5 | G9: Loads are calculated directly from your actual entered 1RM maxes, matching the StrengthBender app (Program 2.0).
B10: Bent-Over Row (Base W1) | C10: 135 | D10: Linear Load Progression | E10: Progresses +5 lbs/week: =C10 + (Week - 1)*5 | G10: • RPE Scale Guide
B11: 💡 Blue cells above (C7:C10) are interactive. Change them anytime; all 268 exercise loads across the workbook update automatically! | G11: @6: 4 reps in reserve (crisp speed) @7: 3 reps in reserve (clean, controlled) @8: 2 reps in reserve (solid effort) @8.5-9: 1-2 reps in reserve (heavy single) @10: 0 reps in reserve (PR test)
G12: • Deloads (Weeks 5 & 10)
B13: 2. 13-WEEK MACROCYCLE PERIODIZATION ROADMAP
B14: Week | C14: Phase | D14: Strategic Objective & Role in Cycle | G14: Primary Prescription | I14: Target RPE
B15: W1 | C15: Accumulation | D15: Base building: Groove movement patterns, top single @85%, back-offs 4x4 @70%, bent-over row base. | G15: Top 1x1 @85% (RPE 7.5-8) + 4x4 @70% | I15: RPE 7-8
B16: W2 | C16: Accumulation | D16: Volume accumulation: +1 set on back-off, +5 lb on variants & rows. | G16: Top 1x1 @85% + 5x4 @70% | I16: RPE 7-8
B17: W3 | C17: Accumulation | D17: Volume peak start: Sets rise on Squat/Bench, Deadlift picks up 4th set, variants +10 lb. | G17: Top 1x1 @86% + 5x4 @71% | I17: RPE 7-8
B18: W4 | C18: Accumulation Peak | D18: Block fatigue peak: Heaviest accumulation sessions before reset. Top single @87%. | G18: Top 1x1 @87% + 5x4 @72% | I18: RPE 8
B19: W5 | C19: Deload | D19: Fatigue dissipation: Deload volume and intensity to absorb training stress. | G19: 2-3x3 @ 55-60% Max | I19: RPE 6 (Recovery)
B20: W6 | C20: Intensification | D20: Neural drive shift: Volume drops, bar intensity jumps into 90s on top singles. | G20: Top 1x1 @90% + 4x3 @75% | I20: RPE 8 (Rested)
B21: W7 | C21: Intensification | D21: Doubles transition: Heavy doubles commence across main lifts, high-bar squat introduced. | G21: Top 1x1 @91% + 4x3 @76% | I21: RPE 8
B22: W8 | C22: Intensification | D22: Heavy doubles threshold: Competition attempt weight familiarity, top single @92%. | G22: Top 1x1 @92% + 4x2 @78% | I22: RPE 8-9 (Heavy)
B23: W9 | C23: Top of Intensification | D23: Final near-max check: Controlled heavy doubles + speed-gated optional singles. | G23: Top 1x1 @92% + 3x2 @80% | I23: RPE 8-9 (Strict Gate)
B24: W10 | C24: Deload | D24: Pre-peak reset: Flush nervous system fatigue and supercompensate before peaking. | G24: 2-3x2 @ 60% Max | I24: RPE 6 (Recovery)
B25: W11 | C25: Peak / Realization | D25: Heavy single realization: 90% top single + back-off doubles at 82%. Accessory volume cut. | G25: Top 1x1 @90% + 3x2 @82% | I25: RPE 8
... B27: W13 | C27: Testing | D27: PR Test Week (8 Days): Light activation Day 1, individual PR days (Bench D2, Squat D4, DL D8) with rest separation. | G27: Openers @ 90% -> 2nd/3rd PR Attempts | I27: RPE 9.5-10 (All-Out PRs)
B30: 3. PROJECTED PR TARGETS (13-WEEK ADAPTATION MODEL)
B31: Lift | C31: Current 1RM | D31: Est. Weekly Adaptation | E31: Conservative PR (+2.5%) | F31: Target Base PR (+5%) | G31: Aggressive PR (+7.5%) | H31: Testing Session
B32: Back Squat | C32: =C7 | D32: +0.4% / week | E32: =ROUND(C7*1.025/5, 0)*5 | F32: =ROUND(C7*1.05/5, 0)*5 | G32: =ROUND(C7*1.075/5, 0)*5 | H32: Week 13 — Day 4 (Squat Test)
B33: Bench Press | C33: =C8 | D33: +0.4% / week | E33: =ROUND(C8*1.025/5, 0)*5 | F33: =ROUND(C8*1.05/5, 0)*5 | G33: =ROUND(C8*1.075/5, 0)*5 | H33: Week 13 — Day 2 (Bench Test)
B34: Deadlift | C34: =C9 | D34: +0.4% / week | E34: =ROUND(C9*1.025/5, 0)*5 | F34: =ROUND(C9*1.05/5, 0)*5 | G34: =ROUND(C9*1.075/5, 0)*5 | H34: Week 13 — Day 8 (Deadlift Test)

Sheet Master Program (All Weeks)
A1: CHIKO_LIFTS : MASTER 13-WEEK TRAINING PROGRAM LOG
A2: All 13 Weeks, 68 Sessions & 268 Exercises — Dynamic Live Prescribed Load Formulas Linked Directly to Athlete 1RMs
A3: Week | B3: Phase | C3: Day # | D3: Day Label / Focus | E3: Ex # | F3: Exercise Name | G3: Type | H3: Lift Ref | I3: Sets | J3: Reps | K3: % 1RM | L3: Prescribed Load (lbs) | M3: Target RPE | N3: Prescription / Execution Notes | O3: Actual Load (lbs) | P3: Actual Reps / Notes | Q3: Done?
A4: 1 | B4: Accumulation | C4: 1 | D4: Monday — Squat | E4: 1 | F4: Back squat — top single | G4: Main Lift | H4: SQUAT | I4: 1 | J4: 1 | K4: 85% | L4: =ROUND('Setup & Dashboard'!$C$7*0.85/5, 0)*5 | M4: RPE 7.5-8 | N4: Smooth single, no grind | Q4: [ ]
A5: 1 | B5: Accumulation | C5: 1 | D5: Monday — Squat | E5: 2 | F5: Back squat — back-off | G5: Main Lift | H5: SQUAT | I5: 4 | J5: 4 | K5: 70% | L5: =ROUND('Setup & Dashboard'!$C$7*0.7/5, 0)*5 | M5: RPE 7 | Q5: [ ]
A6: 1 | B6: Accumulation | C6: 1 | D6: Monday — Squat | E6: 3 | F6: Bulgarian split squat | G6: Accessory | H6: - | I6: 3 | J6: 10/leg | Q6: [ ]
A7: 1 | B7: Accumulation | C7: 1 | D7: Monday — Squat | E7: 4 | F7: Seated leg curl | G7: Accessory | H7: - | I7: 3 | J7: 12 | Q7: [ ]
A8: 1 | B8: Accumulation | C8: 1 | D8: Monday — Squat | E8: 5 | F8: Pallof press | G8: Accessory | H8: - | I8: 3 | J8: 10/side | Q8: [ ]
A9: 1 | B9: Accumulation | C9: 1 | D9: Monday — Squat | E9: 6 | F9: Standing calf raise | G9: Accessory | H9: - | I9: 3 | J9: 15 | Q9: [ ]
A10: 1 | B10: Accumulation | C10: 2 | D10: Tuesday — Bench | E10: 1 | F10: Bench press | G10: Main Lift | H10: BENCH | I10: 6 | J10: 4 | K10: 70% | L10: =ROUND('Setup & Dashboard'!$C$8*0.7/5, 0)*5 | M10: RPE 7 | Q10: [ ]
A11: 1 | B11: Accumulation | C11: 2 | D11: Tuesday — Bench | E11: 2 | F11: Close-grip bench | G11: Accessory | H11: - | I11: 3 | J11: 6 | M11: RPE 7 | Q11: [ ]
A12: 1 | B12: Accumulation | C12: 2 | D12: Tuesday — Bench | E12: 3 | F12: Incline DB press | G12: Accessory | H12: - | I12: 3 | J12: 12 | Q12: [ ]
A13: 1 | B13: Accumulation | C13: 2 | D13: Tuesday — Bench | E13: 4 | F13: Triceps pressdown | G13: Accessory | H13: - | I13: 3 | J13: 12 | Q13: [ ]
A14: 1 | B14: Accumulation | C14: 2 | D14: Tuesday — Bench | E14: 5 | F14: Face pull | G14: Accessory | H14: - | I14: 3 | J14: 15 | Q14: [ ]
A15: 1 | B15: Accumulation | C15: 3 | D15: Thursday — Deadlift | E15: 1 | F15: Deadlift | G15: Main Lift | H15: DEADLIFT | I15: 3 | J15: 4 | K15: 68% | L15: =ROUND('Setup & Dashboard'!$C$9*0.68/5, 0)*5 | M15: RPE 7 | Q15: [ ]
A16: 1 | B16: Accumulation | C16: 3 | D16: Thursday — Deadlift | E16: 2 | F16: 1.5-rep deadlift (knee height) | G16: Main Lift | H16: DEADLIFT | I16: 3 | J16: 3 | K16: 60% | L16: =ROUND('Setup & Dashboard'!$C$9*0.6/5, 0)*5 | N16: Reset every rep; lower to just below knee, return to lockout, then lower fully. W1 60% DL max; add +5 lb/week only if clean and ≤RPE 7. Deload: 2x3 @55% max. | Q16: [ ]
A17: 1 | B17: Accumulation | C17: 3 | D17: Thursday — Deadlift | E17: 3 | F17: Reverse hyper | G17: Accessory | H17: - | I17: 2 | J17: 15 | Q17: [ ]
A18: 1 | B18: Accumulation | C18: 3 | D18: Thursday — Deadlift | E18: 4 | F18: Jefferson curl | G18: Accessory | H18: - | I18: 2 | J18: 8 | Q18: [ ]
A19: 1 | B19: Accumulation | C19: 4 | D19: Friday — Bench variant / upper body | E19: 1 | F19: Tempo bench (3-1-1) | G19: Main Lift | H19: BENCH | I19: 4 | J19: 4 | K19: 65% | L19: =ROUND('Setup & Dashboard'!$C$8*0.65/5, 0)*5 | M19: RPE 6-7 | Q19: [ ]
A20: 1 | B20: Accumulation | C20: 4 | D20: Friday — Bench variant / upper body | E20: 2 | F20: Lat pulldown | G20: Accessory | H20: - | I20: 3 | J20: 12 | Q20: [ ]
A21: 1 | B21: Accumulation | C21: 4 | D21: Friday — Bench variant / upper body | E21: 3 | F21: Lateral raise | G21: Accessory | H21: - | I21: 3 | J21: 15 | Q21: [ ]
A22: 1 | B22: Accumulation | C22: 4 | D22: Friday — Bench variant / upper body | E22: 4 | F22: Curl | G22: Accessory | H22: - | I22: 3 | J22: 12 | Q22: [ ]
A23: 1 | B23: Accumulation | C23: 4 | D23: Friday — Bench variant / upper body | E23: 5 | F23: Pallof press | G23: Accessory | H23: - | I23: 3 | J23: 10/side | Q23: [ ]
A24: 1 | B24: Accumulation | C24: 5 | D24: Saturday — Squat variant + Bent-over row | E24: 1 | F24: Paused squat | G24: Main Lift | H24: SQUAT | I24: 3 | J24: 3 | K24: 70% | L24: =ROUND('Setup & Dashboard'!$C$7*0.7/5, 0)*5 | M24: RPE ≤8 | N24: Clean reps; no grinding | Q24: [ ]
A25: 1 | B25: Accumulation | C25: 5 | D25: Saturday — Squat variant + Bent-over row | E25: 2 | F25: Bent-over row | G25: Accessory | H25: ROW | I25: 4 | J25: 4-6 | K25: Linear +5lb | L25: ='Setup & Dashboard'!$C$10+(1-1)*5 | N25: 4 strict sets. Add 5 lb next exposure only when every set is clean and ≤RPE 8; deload load/reps, no failure. | Q25: [ ]
A26: 1 | B26: Accumulation | C26: 5 | D26: Saturday — Squat variant + Bent-over row | E26: 3 | F26: Reverse hyper | G26: Accessory | H26: - | I26: 2 | J26: 12 | Q26: [ ]
A27: 1 | B27: Accumulation | C27: 5 | D27: Saturday — Squat variant + Bent-over row | E27: 4 | F27: GHR or Nordic curl | G27: Accessory | H27: - | I27: 3 | J27: 8 | Q27: [ ]
A28: 1 | B28: Accumulation | C28: 5 | D28: Saturday — Squat variant + Bent-over row | E28: 5 | F28: Jefferson curl | G28: Accessory | H28: - | I28: 1 | J28: 8 | Q28: [ ]
A29: 2 | B29: Accumulation | C29: 1 | D29: Monday — Squat | E29: 1 | F29: Back squat — top single | G29: Main Lift | H29: SQUAT | I29: 1 | J29: 1 | K29: 86% | L29: =ROUND('Setup & Dashboard'!$C$7*0.86/5, 0)*5 | M29: RPE 7.5-8 | N29: Smooth single, no grind | Q29: [ ]
A30: 2 | B30: Accumulation | C30: 1 | D30: Monday — Squat | E30: 2 | F30: Back squat — back-off | G30: Main Lift | H30: SQUAT | I30: 5 | J30: 4 | K30: 73% | L30: =ROUND('Setup & Dashboard'!$C$7*0.73/5, 0)*5 | M30: RPE 7 | Q30: [ ]
A31: 2 | B31: Accumulation | C31: 1 | D31: Monday — Squat | E31: 3 | F31: Bulgarian split squat | G31: Accessory | H31: - | I31: 3 | J31: 10/leg | Q31: [ ]
A32: 2 | B32: Accumulation | C32: 1 | D32: Monday — Squat | E32: 4 | F32: Leg curl | G32: Accessory | H32: - | I32: 3 | J32: 12 | Q32: [ ]
A33: 2 | B33: Accumulation | C33: 1 | D33: Monday — Squat | E33: 5 | F33: Copenhagen plank | G33: Accessory | H33: - | I33: 3 | J33: 20sec/side | Q33: [ ]
A34: 2 | B34: Accumulation | C34: 2 | D34: Tuesday — Bench | E34: 1 | F34: Bench press | G34: Main Lift | H34: BENCH | I34: 7 | J34: 4 | K34: 73% | L34: =ROUND('Setup & Dashboard'!$C$8*0.73/5, 0)*5 | M34: RPE 7 | Q34: [ ]
A35: 2 | B35: Accumulation | C35: 2 | D35: Tuesday — Bench | E35: 2 | F35: Close-grip bench | G35: Accessory | H35: - | I35: 3 | J35: 6 | Q35: [ ]
A36: 2 | B36: Accumulation | C36: 2 | D36: Tuesday — Bench | E36: 3 | F36: Incline DB press | G36: Accessory | H36: - | I36: 3 | J36: 12 | Q36: [ ]
A37: 2 | B37: Accumulation | C37: 2 | D37: Tuesday — Bench | E37: 4 | F37: Triceps pressdown | G37: Accessory | H37: - | I37: 3 | J37: 12 | Q37: [ ]
A38: 2 | B38: Accumulation | C38: 2 | D38: Tuesday — Bench | E38: 5 | F38: Face pull | G38: Accessory | H38: - | I38: 3 | J38: 15 | Q38: [ ]
A39: 2 | B39: Accumulation | C39: 3 | D39: Thursday — Deadlift | E39: 1 | F39: Deadlift | G39: Main Lift | H39: DEADLIFT | I39: 3 | J39: 4 | K39: 72% | L39: =ROUND('Setup & Dashboard'!$C$9*0.72/5, 0)*5 | M39: RPE 7 | Q39: [ ]
A40: 2 | B40: Accumulation | C40: 3 | D40: Thursday — Deadlift | E40: 2 | F40: 1.5-rep deadlift (knee height) | G40: Main Lift | H40: DEADLIFT | I40: 3 | J40: 3 | K40: 60% + 5 lb | L40: =ROUND('Setup & Dashboard'!$C$9*0.6/5, 0)*5+5 | N40: Reset every rep; lower to just below knee, return to lockout, then lower fully. W1 60% DL max; add +5 lb/week only if clean and ≤RPE 7. Deload: 2x3 @55% max. | Q40: [ ]
...

Sheet Block 1 (W1-5)
A1: CHIKO_LIFTS : BLOCK 1 (W1-5) (WEEKS 1–5)
A2: Foundation & Volume Accumulation, Unilateral Hypertrophy & Week 5 Fatigue Deload
A4: WEEK 1 — ACCUMULATION
A5: Day 1 : Monday — Squat
A6: 💡 Coaching Rationale: The cycle opens with a top single at 85% of max. It's not a max test. It's a smooth, no-grind single at RPE 7.5-8 that gets you used to heavier weight on your back from day one. The 4x4 back-offs at 70% of max are the real volume work, kept well short of failure so you groove the pattern. Split squats and leg curls build the single-leg stability and hamstring strength that heavier squats will need later.
A7: # | B7: Exercise | C7: Type | D7: Sets | E7: Reps | F7: % 1RM | G7: Prescribed (lbs) | H7: RPE | I7: Technique Notes | J7: Actual Wt | K7: Reps/Notes | L7: Done
A8: 1 | B8: Back squat — top single | C8: Main | D8: 1 | E8: 1 | F8: 85% | G8: =ROUND('Setup & Dashboard'!$C$7*0.85/5, 0)*5 | H8: @7.5-8 | I8: Smooth single, no grind | L8: [ ]
A9: 2 | B9: Back squat — back-off | C9: Main | D9: 4 | E9: 4 | F9: 70% | G9: =ROUND('Setup & Dashboard'!$C$7*0.7/5, 0)*5 | H9: @7 | L9: [ ]
A10: 3 | B10: Bulgarian split squat | C10: Acc | D10: 3 | E10: 10/leg | L10: [ ]
A11: 4 | B11: Seated leg curl | C11: Acc | D11: 3 | E11: 12 | L11: [ ]
A12: 5 | B12: Pallof press | C12: Acc | D12: 3 | E12: 10/side | L12: [ ]
A13: 6 | B13: Standing calf raise | C13: Acc | D13: 3 | E13: 15 | L13: [ ]
A15: Day 2 : Tuesday — Bench
A16: 💡 Coaching Rationale: Bench starts with 6x4 at 70% of max. That's more sets than squat because bench recovers faster and handles volume well. Close-grip bench and triceps work start building lockout strength for the heavier weeks. Face pulls keep the rear delts and rotator cuff balanced against all the pressing.
A17: # | B17: Exercise | C17: Type | D17: Sets | E17: Reps | F17: % 1RM | G17: Prescribed (lbs) | H17: RPE | I17: Technique Notes | J17: Actual Wt | K17: Reps/Notes | L17: Done
A18: 1 | B18: Bench press | C18: Main | D18: 6 | E18: 4 | F18: 70% | G18: =ROUND('Setup & Dashboard'!$C$8*0.7/5, 0)*5 | H18: @7 | L18: [ ]
A19: 2 | B19: Close-grip bench | C19: Acc | D19: 3 | E19: 6 | H19: @7 | L19: [ ]
A20: 3 | B20: Incline DB press | C20: Acc | D20: 3 | E20: 12 | L20: [ ]
A21: 4 | B21: Triceps pressdown | C21: Acc | D21: 3 | E21: 12 | L21: [ ]
A22: 5 | B22: Face pull | C22: Acc | D22: 3 | E22: 15 | L22: [ ]
A24: Day 3 : Thursday — Deadlift
A25: 💡 Coaching Rationale: Deadlift is the lightest main lift relative to your max (68%) because it costs the most recovery. The 1.5-rep deadlift from knee height starts at 60% of your deadlift max. Each rep goes lockout → just below the knee → back to lockout → floor, with a reset every rep. This builds strength in the knee-to-lockout range under control. Only add the weekly 5 lb if every rep is clean and RPE 7 or lower.
A26: # | B26: Exercise | C26: Type | D26: Sets | E26: Reps | F26: % 1RM | G26: Prescribed (lbs) | H26: RPE | I26: Technique Notes | J26: Actual Wt | K26: Reps/Notes | L26: Done
A27: 1 | B27: Deadlift | C27: Main | D27: 3 | E27: 4 | F27: 68% | G27: =ROUND('Setup & Dashboard'!$C$9*0.68/5, 0)*5 | H27: @7 | L27: [ ]
A28: 2 | B28: 1.5-rep deadlift (knee height) | C28: Main | D28: 3 | E28: 3 | F28: 60% | G28: =ROUND('Setup & Dashboard'!$C$9*0.6/5, 0)*5 | I28: Reset every rep; lower to just below knee, return to lockout, then lower fully. W1 60% DL max; add +5 lb/week only if clean and ≤RPE 7. Deload: 2x3 @55% max. | L28: [ ]
A29: 3 | B29: Reverse hyper | C29: Acc | D29: 2 | E29: 15 | L29: [ ]
A30: 4 | B30: Jefferson curl | C30: Acc | D30: 2 | E30: 8 | L30: [ ]
A32: Day 4 : Friday — Bench variant / upper body
A33: 💡 Coaching Rationale: This is a second bench day, not a second heavy bench day. The 3-1-1 tempo at 65% keeps the weight light while you practice bar path and control. Pulldowns and arm work round out the upper body. Rowing has moved to Saturday as a heavy bent-over row.
A34: # | B34: Exercise | C34: Type | D34: Sets | E34: Reps | F34: % 1RM | G34: Prescribed (lbs) | H34: RPE | I34: Technique Notes | J34: Actual Wt | K34: Reps/Notes | L34: Done
A35: 1 | B35: Tempo bench (3-1-1) | C35: Main | D35: 4 | E35: 4 | F35: 65% | G35: =ROUND('Setup & Dashboard'!$C$8*0.65/5, 0)*5 | H35: @6-7 | L35: [ ]
A36: 2 | B36: Lat pulldown | C36: Acc | D36: 3 | E36: 12 | L36: [ ]
A37: 3 | B37: Lateral raise | C37: Acc | D37: 3 | E37: 15 | L37: [ ]
A38: 4 | B38: Curl | C38: Acc | D38: 3 | E38: 12 | L38: [ ]
A39: 5 | B39: Pallof press | C39: Acc | D39: 3 | E39: 10/side | L39: [ ]
A41: Day 5 : Saturday — Squat variant + Bent-over row
A42: 💡 Coaching Rationale: Paused squat at 70% of max builds strength in the bottom of the squat. From here it goes up a fixed 5 lb each week instead of following a percentage. The bent-over row replaces the old rack pull slot: 4 strict sets of 4-6, adding 5 lb next time only when every set is clean and RPE 8 or lower. Never row to failure.
A43: # | B43: Exercise | C43: Type | D43: Sets | E43: Reps | F43: % 1RM | G43: Prescribed (lbs) | H43: RPE | I43: Technique Notes | J43: Actual Wt | K43: Reps/Notes | L43: Done
A44: 1 | B44: Paused squat | C44: Main | D44: 3 | E44: 3 | F44: 70% | G44: =ROUND('Setup & Dashboard'!$C$7*0.7/5, 0)*5 | H44: @≤8 | I44: Clean reps; no grinding | L44: [ ]
A45: 2 | B45: Bent-over row | C45: Acc | D45: 4 | E45: 4-6 | F45: Row +5# | G45: ='Setup & Dashboard'!$C$10+(1-1)*5 | I45: 4 strict sets. Add 5 lb next exposure only when every set is clean and ≤RPE 8; deload load/reps, no failure. | L45: [ ]
...

Sheet Block 2 (W6-10)
A1: CHIKO_LIFTS : BLOCK 2 (W6-10) (WEEKS 6–10)
A2: Neural Drive Shift, Heavy Doubles Threshold, High-Bar Squat & Week 10 Pre-Peak Deload
A4: WEEK 6 — INTENSIFICATION
A5: Day 1 : Monday — Squat
A6: 💡 Coaching Rationale: Intensification starts. The top single jumps to 90% of max, but it's capped at RPE 8. If it isn't smooth, don't push it. The back-offs drop to 5x3 at 83%. Because you're rested, RPE 8 here should feel similar to Week 4's RPE 8 even though the weight is heavier.
A7: # | B7: Exercise | C7: Type | D7: Sets | E7: Reps | F7: % 1RM | G7: Prescribed (lbs) | H7: RPE | I7: Technique Notes | J7: Actual Wt | K7: Reps/Notes | L7: Done
A8: 1 | B8: Squat — top single | C8: Main | D8: 1 | E8: 1 | F8: 90% | G8: =ROUND('Setup & Dashboard'!$C$7*0.9/5, 0)*5 | H8: @8 cap | I8: Smooth single, no grind | L8: [ ]
A9: 2 | B9: Squat — back-off | C9: Main | D9: 5 | E9: 3 | F9: 83% | G9: =ROUND('Setup & Dashboard'!$C$7*0.83/5, 0)*5 | H9: @8 | L9: [ ]
A10: 3 | B10: Bulgarian split squat | C10: Acc | D10: 3 | E10: 8 | L10: [ ]
A11: 4 | B11: Leg curl | C11: Acc | D11: 3 | E11: 10 | L11: [ ]
A12: 5 | B12: Copenhagen plank | C12: Acc | D12: 3 | E12: 20sec/side | L12: [ ]
A14: Day 2 : Tuesday — Bench
A15: 💡 Coaching Rationale: Bench is 7x3 at 83% of max, RPE 8: fewer reps per set and heavier weight than the accumulation block.
A16: # | B16: Exercise | C16: Type | D16: Sets | E16: Reps | F16: % 1RM | G16: Prescribed (lbs) | H16: RPE | I16: Technique Notes | J16: Actual Wt | K16: Reps/Notes | L16: Done
A17: 1 | B17: Bench | C17: Main | D17: 7 | E17: 3 | F17: 83% | G17: =ROUND('Setup & Dashboard'!$C$8*0.83/5, 0)*5 | H17: @8 | L17: [ ]
A18: 2 | B18: Close-grip bench | C18: Acc | D18: 3 | E18: 5 | L18: [ ]
A19: 3 | B19: Incline DB press | C19: Acc | D19: 3 | E19: 8-10 | L19: [ ]
A20: 4 | B20: Triceps pressdown | C20: Acc | D20: 3 | E20: 12 | L20: [ ]
A21: 5 | B21: Face pull | C21: Acc | D21: 3 | E21: 15 | L21: [ ]
A23: Day 3 : Thursday — Deadlift
A24: 💡 Coaching Rationale: Deadlift drops to 3 sets (3x3 at 82%) as the weight goes up, protecting recovery. The 1.5-rep deadlift picks up at base + 25 lb. The deload week counts on the weekly calendar, so this is 5 weeks of progression from Week 1.
A25: # | B25: Exercise | C25: Type | D25: Sets | E25: Reps | F25: % 1RM | G25: Prescribed (lbs) | H25: RPE | I25: Technique Notes | J25: Actual Wt | K25: Reps/Notes | L25: Done
A26: 1 | B26: Deadlift | C26: Main | D26: 3 | E26: 3 | F26: 82% | G26: =ROUND('Setup & Dashboard'!$C$9*0.82/5, 0)*5 | H26: @8 | L26: [ ]
A27: 2 | B27: 1.5-rep deadlift (knee height) | C27: Main | D27: 3 | E27: 3 | F27: 60% +25# | G27: =ROUND('Setup & Dashboard'!$C$9*0.6/5, 0)*5+25 | I27: Reset every rep; lower to just below knee, return to lockout, then lower fully. W1 60% DL max; add +5 lb/week only if clean and ≤RPE 7. Deload: 2x3 @55% max. | L27: [ ]
A28: 3 | B28: Reverse hyper | C28: Acc | D28: 2 | E28: 12 | L28: [ ]
A29: 4 | B29: Jefferson curl | C29: Acc | D29: 2 | E29: 8 | L29: [ ]
A31: Day 4 : Friday — Bench variant / upper body
A32: 💡 Coaching Rationale: Spoto press goes to 65% but stays a submaximal support day. This session's job is technique and upper-body support, not a new heavy weight.
A33: # | B33: Exercise | C33: Type | D33: Sets | E33: Reps | F33: % 1RM | G33: Prescribed (lbs) | H33: RPE | I33: Technique Notes | J33: Actual Wt | K33: Reps/Notes | L33: Done
A34: 1 | B34: Spoto press | C34: Main | D34: 4 | E34: 3 | F34: 65% | G34: =ROUND('Setup & Dashboard'!$C$8*0.65/5, 0)*5 | H34: @7 | L34: [ ]
A35: 2 | B35: Lat pulldown | C35: Acc | D35: 3 | E35: 10 | L35: [ ]
A36: 3 | B36: Lateral raise | C36: Acc | D36: 3 | E36: 15 | L36: [ ]
A37: 4 | B37: Curl | C37: Acc | D37: 3 | E37: 10-12 | L37: [ ]
A38: 5 | B38: Pallof press | C38: Acc | D38: 3 | E38: 10/side | L38: [ ]
A40: Day 5 : Saturday — Squat variant + Bent-over row
A41: 💡 Coaching Rationale: Paused squat resumes its progression at base + 20 lb for 3x4. This is its last week before the switch to high-bar squat.
A42: # | B42: Exercise | C42: Type | D42: Sets | E42: Reps | F42: % 1RM | G42: Prescribed (lbs) | H42: RPE | I42: Technique Notes | J42: Actual Wt | K42: Reps/Notes | L42: Done
A43: 1 | B43: Paused squat | C43: Main | D43: 3 | E43: 4 | F43: 70% +20# | G43: =ROUND('Setup & Dashboard'!$C$7*0.7/5, 0)*5+20 | H43: @≤8 | I43: Clean reps; no grinding | L43: [ ]
A44: 2 | B44: Bent-over row | C44: Acc | D44: 4 | E44: 4-6 | F44: Row +5# | G44: ='Setup & Dashboard'!$C$10+(6-1)*5 | I44: 4 strict sets. Add 5 lb next exposure only when every set is clean and ≤RPE 8; deload load/reps, no failure. | L44: [ ]
A45: 3 | B45: Reverse hyper | C45: Acc | D45: 2 | E45: 12 | L45: [ ]
...

Sheet Block 3 (W11-12)
A1: CHIKO_LIFTS : BLOCK 3 (W11-12) (WEEKS 11–12)
A2: Neuromuscular Realization, Heavy Singles Prep & Pre-Meet Sharpening Taper
A4: WEEK 11 — PEAK / REALIZATION
A5: Day 1 : Monday — Squat
A6: 💡 Coaching Rationale: Peak week starts with a true heavy single at 90% of max, RPE 8-9, then 2 crisp back-off singles at 82%, RPE 6-7. The singles keep your nervous system sharp without the fatigue of real volume.
A7: # | B7: Exercise | C7: Type | D7: Sets | E7: Reps | F7: % 1RM | G7: Prescribed (lbs) | H7: RPE | I7: Technique Notes | J7: Actual Wt | K7: Reps/Notes | L7: Done
A8: 1 | B8: Squat — top single | C8: Main | D8: 1 | E8: 1 | F8: 90% | G8: =ROUND('Setup & Dashboard'!$C$7*0.9/5, 0)*5 | H8: @8-9 | L8: [ ]
A9: 2 | B9: Squat — back-off | C9: Main | D9: 2 | E9: 1 | F9: 82% | G9: =ROUND('Setup & Dashboard'!$C$7*0.82/5, 0)*5 | H9: @6-7 | I9: Crisp | L9: [ ]
A10: 3 | B10: Copenhagen plank | C10: Acc | D10: 2 | E10: 15sec/side | L10: [ ]
A11: 4 | B11: Pallof press | C11: Acc | D11: 2 | E11: 8/side | L11: [ ]
A13: Day 2 : Tuesday — Bench
A14: 💡 Coaching Rationale: Bench now gets its own top single at 90% of max (RPE 8-9 cap), then 4 back-off singles at 82%. That's two more back-off sets than the original 2x1 because bench recovers fastest. Stop the back-offs if bar speed drops.
A15: # | B15: Exercise | C15: Type | D15: Sets | E15: Reps | F15: % 1RM | G15: Prescribed (lbs) | H15: RPE | I15: Technique Notes | J15: Actual Wt | K15: Reps/Notes | L15: Done
A16: 1 | B16: Bench — top single | C16: Main | D16: 1 | E16: 1 | F16: 90% | G16: =ROUND('Setup & Dashboard'!$C$8*0.9/5, 0)*5 | H16: @8-9 cap | L16: [ ]
A17: 2 | B17: Bench — back-off | C17: Main | D17: 4 | E17: 1 | F17: 82% | G17: =ROUND('Setup & Dashboard'!$C$8*0.82/5, 0)*5 | I17: Crisp reps, stop if speed drops | L17: [ ]
A18: 3 | B18: Close-grip bench | C18: Acc | D18: 2 | E18: 3 | L18: [ ]
A19: 4 | B19: Face pull | C19: Acc | D19: 2 | E19: 15 | L19: [ ]
A21: Day 3 : Thursday — Deadlift
A22: 💡 Coaching Rationale: One heavy deadlift single at 88%, RPE 8-9. The 1.5-rep deadlift continues at base + 50 lb for 3x3. Hold the weight or cut a set if the single was hard, because test week is close.
A23: # | B23: Exercise | C23: Type | D23: Sets | E23: Reps | F23: % 1RM | G23: Prescribed (lbs) | H23: RPE | I23: Technique Notes | J23: Actual Wt | K23: Reps/Notes | L23: Done
A24: 1 | B24: Deadlift | C24: Main | D24: 1 | E24: 1 | F24: 88% | G24: =ROUND('Setup & Dashboard'!$C$9*0.88/5, 0)*5 | H24: @8-9 | L24: [ ]
A25: 2 | B25: 1.5-rep deadlift (knee height) | C25: Main | D25: 3 | E25: 3 | F25: 60% +50# | G25: =ROUND('Setup & Dashboard'!$C$9*0.6/5, 0)*5+50 | I25: Reset every rep; lower to just below knee, return to lockout, then lower fully. W1 60% DL max; add +5 lb/week only if clean and ≤RPE 7. Deload: 2x3 @55% max. | L25: [ ]
A26: 3 | B26: Reverse hyper | C26: Acc | D26: 2 | E26: 10 | L26: [ ]
A28: Day 4 : Friday — Bench variant / upper body
A29: 💡 Coaching Rationale: Competition-style bench at 75%, lighter than Week 9's version. As testing gets closer, every non-peak day should get easier.
A30: # | B30: Exercise | C30: Type | D30: Sets | E30: Reps | F30: % 1RM | G30: Prescribed (lbs) | H30: RPE | I30: Technique Notes | J30: Actual Wt | K30: Reps/Notes | L30: Done
A31: 1 | B31: Competition-style bench | C31: Main | D31: 2 | E31: 2 | F31: 75% | G31: =ROUND('Setup & Dashboard'!$C$8*0.75/5, 0)*5 | H31: @7 | L31: [ ]
A32: 2 | B32: Lat pulldown | C32: Acc | D32: 2 | E32: 8-10 | L32: [ ]
A33: 3 | B33: Lateral raise | C33: Acc | D33: 2 | E33: 12-15 | L33: [ ]
A35: Day 5 : Saturday — Squat variant + Bent-over row
A36: 💡 Coaching Rationale: High-bar squat resumes progression at base + 15 lb for 2x2. Rows continue, kept clean and well short of failure.
A37: # | B37: Exercise | C37: Type | D37: Sets | E37: Reps | F37: % 1RM | G37: Prescribed (lbs) | H37: RPE | I37: Technique Notes | J37: Actual Wt | K37: Reps/Notes | L37: Done
A38: 1 | B38: High-bar squat | C38: Main | D38: 2 | E38: 2 | F38: 75% +15# | G38: =ROUND('Setup & Dashboard'!$C$7*0.75/5, 0)*5+15 | H38: @≤8 | I38: Clean reps; no grinding | L38: [ ]
A39: 2 | B39: Bent-over row | C39: Acc | D39: 4 | E39: 4-6 | F39: Row +5# | G39: ='Setup & Dashboard'!$C$10+(11-1)*5 | I39: 4 strict sets. Add 5 lb next exposure only when every set is clean and ≤RPE 8; deload load/reps, no failure. | L39: [ ]
A40: 3 | B40: Reverse hyper | C40: Acc | D40: 1 | E40: 10 | L40: [ ]
A42: WEEK 12 — TAPER
A43: Day 1 : Monday — Squat
A44: 💡 Coaching Rationale: Taper week. The top single is capped at RPE 7 (80% of max) and should be crisp only. The 2 back-off singles at 82% are taper volume at RPE 6-7. Note: the back-off singles are prescribed slightly heavier than the top single. Nothing here is a max effort. The goal is to stay sharp while fatigue drops.
A45: # | B45: Exercise | C45: Type | D45: Sets | E45: Reps | F45: % 1RM | G45: Prescribed (lbs) | H45: RPE | I45: Technique Notes | J45: Actual Wt | K45: Reps/Notes | L45: Done
A46: 1 | B46: Squat — top single | C46: Main | D46: 1 | E46: 1 | F46: 80% | G46: =ROUND('Setup & Dashboard'!$C$7*0.8/5, 0)*5 | H46: @7 cap | I46: Crisp only | L46: [ ]
...

Sheet Week 13 PR Testing Plan
A1: CHIKO_LIFTS : WEEK 13 PEAKING & PR TESTING MASTER SCHEDULE
A2: Official 8-Day Competition Peaking Protocol — Activation Day + 3 Dedicated PR Test Days with Strategic Full-Rest Spacing
A4: A. 8-DAY PR TESTING TIMELINE & SCHEDULE
A5: Day # | B5: Role | C5: Status | D5: Session Focus | E5: Key Protocol | F5: Coaching Strategy
A6: Day 1 | B6: Activation | C6: Lifting | D6: Day 1 — Light activation | E6: Squat & Bench 2x3 @ 50% Max | F6: Grease the motor pattern, wake up the nervous system, zero fatigue.
A7: Day 2 | B7: Bench PR | C7: Lifting | D7: Day 2 — Bench PR test | E7: Opener @ 90% -> 2nd Attempt PR -> 3rd Attempt Max | F7: Bench tested first when whole-body nervous system is freshest.
A8: Day 3 | B8: Rest | C8: Rest | D8: Day 3 — Mandatory Rest | E8: Full rest; zero lifting | F8: Clear upper body fatigue; hydrate and eat before Squat day.
A9: Day 4 | B9: Squat PR | C9: Lifting | D9: Day 4 — Squat PR test | E9: Opener @ 90% -> 2nd Attempt PR -> 3rd Attempt Max | F9: Test Squat. Warm up thoroughly with empty bar and gradual plate jumps.
A10: Day 5 | B10: Rest | C10: Rest | D10: Day 5 — Rest / recovery | E10: Full rest & light walking | F10: Clear spinal compression and lower body fatigue from Squatting.
A11: Day 6 | B11: Rest | C11: Rest | D11: Day 6 — Rest / full recovery | E11: Full rest & nutrition | F11: Prep nervous system for Deadlift peak.
A12: Day 7 | B12: Rest | C12: Rest | D12: Day 7 — Rest / full recovery | E12: Full rest & mobility | F12: Final rest day. Total CNS restoration before heaviest pull.
A13: Day 8 | B13: Deadlift PR | C13: Lifting | D13: Day 8 — Deadlift PR test | E13: Opener @ 90% -> 2nd Attempt PR -> 3rd Attempt Max | F13: Grand finale: Deadlift PR test. 3 days of rest guaranteed maximum supercompensation.
A16: B. OFFICIAL ATTEMPT SELECTION MATRIX & RECORD BOARD (LINKED TO YOUR MAXES)
A17: Testing Lift | B17: Testing Day | C17: Current 1RM | D17: Attempt 1 (Opener @90%) | E17: Attempt 2 (Target PR) | F17: Attempt 3 (Peak PR) | G17: Official Best PR Hit | H17: Net PR Gain (lbs) | I17: Notes / Meet Video Link
A18: Bench Press | B18: Day 2 | C18: ='Setup & Dashboard'!$C$8 | D18: =ROUND('Setup & Dashboard'!$C$8*0.9/5, 0)*5 | E18: =ROUND('Setup & Dashboard'!$C$8*1.025/5, 0)*5 | F18: =ROUND('Setup & Dashboard'!$C$8*1.05/5, 0)*5 | H18: =IF(G18>0, G18-C18, "-")
A19: Back Squat | B19: Day 4 | C19: ='Setup & Dashboard'!$C$7 | D19: =ROUND('Setup & Dashboard'!$C$7*0.9/5, 0)*5 | E19: =ROUND('Setup & Dashboard'!$C$7*1.025/5, 0)*5 | F19: =ROUND('Setup & Dashboard'!$C$7*1.05/5, 0)*5 | H19: =IF(G19>0, G19-C19, "-")
A20: Deadlift | B20: Day 8 | C20: ='Setup & Dashboard'!$C$9 | D20: =ROUND('Setup & Dashboard'!$C$9*0.9/5, 0)*5 | E20: =ROUND('Setup & Dashboard'!$C$9*1.025/5, 0)*5 | F20: =ROUND('Setup & Dashboard'!$C$9*1.05/5, 0)*5 | H20: =IF(G20>0, G20-C20, "-")
A23: C. ATTEMPT DISCIPLINE & PEAKING RULES
A24: • Opener (Attempt 1 @ 90%) | B24: Your opener MUST be crisp and confident (~RPE 8.5). If your opener is a grind, you DO NOT increase weight on Attempt 2. Repeat or stay conservative.
A25: • Second Attempt (Target PR) | B25: If Opener is fast and clean, jump +10 to +20 lbs to lock in your official new Personal Record. This guarantees you leave the session with a verified PR in the books.
A26: • Third Attempt (Aggressive Reach) | B26: Take this attempt ONLY if Attempt 2 moved with zero technical compromise and bar speed was solid. Put everything on the platform!
A27: • Rest Between Attempts | B27: Take 5 to 7 full minutes of rest between PR attempts. Neuromuscular ATP recovery requires full time.

Sheet Coaching Guide (68 Sessions)
A1: CHIKO_LIFTS : MASTER COACHING GUIDE & SESSION RATIONALE
A2: Comprehensive Session-by-Session Tactical Breakdown, Energy Management, Stimulus Objectives & Recovery Directives
A3: Week | B3: Phase | C3: Day # | D3: Day Label / Session Title | E3: Key Lift Focus | F3: Detailed Coaching Rationale & Strategic Objective | G3: Completed
A4: 1 | B4: Accumulation | C4: 1 | D4: Monday — Squat | E4: Back squat — top single, Back squat — back-off | F4: The cycle opens with a top single at 85% of max. It's not a max test. It's a smooth, no-grind single at RPE 7.5-8 that gets you used to heavier weight on your back from day one. The 4x4 back-offs at 70% of max are the real volume work, kept well short of failure so you groove the pattern. Split squats and leg curls build the single-leg stability and hamstring strength that heavier squats will need later. | G4: [ ]
A5: 1 | B5: Accumulation | C5: 2 | D5: Tuesday — Bench | E5: Bench press | F5: Bench starts with 6x4 at 70% of max. That's more sets than squat because bench recovers faster and handles volume well. Close-grip bench and triceps work start building lockout strength for the heavier weeks. Face pulls keep the rear delts and rotator cuff balanced against all the pressing. | G5: [ ]
A6: 1 | B6: Accumulation | C6: 3 | D6: Thursday — Deadlift | E6: Deadlift, 1.5-rep deadlift (knee height) | F6: Deadlift is the lightest main lift relative to your max (68%) because it costs the most recovery. The 1.5-rep deadlift from knee height starts at 60% of your deadlift max. Each rep goes lockout → just below the knee → back to lockout → floor, with a reset every rep. This builds strength in the knee-to-lockout range under control. Only add the weekly 5 lb if every rep is clean and RPE 7 or lower. | G6: [ ]
A7: 1 | B7: Accumulation | C7: 4 | D7: Friday — Bench variant / upper body | E7: Tempo bench (3-1-1) | F7: This is a second bench day, not a second heavy bench day. The 3-1-1 tempo at 65% keeps the weight light while you practice bar path and control. Pulldowns and arm work round out the upper body. Rowing has moved to Saturday as a heavy bent-over row. | G7: [ ]
A8: 1 | B8: Accumulation | C8: 5 | D8: Saturday — Squat variant + Bent-over row | E8: Paused squat | F8: Paused squat at 70% of max builds strength in the bottom of the squat. From here it goes up a fixed 5 lb each week instead of following a percentage. The bent-over row replaces the old rack pull slot: 4 strict sets of 4-6, adding 5 lb next time only when every set is clean and RPE 8 or lower. Never row to failure. | G8: [ ]
A9: 2 | B9: Accumulation | C9: 1 | D9: Monday — Squat | E9: Back squat — top single, Back squat — back-off | F9: The top single goes up to 86% of max. The back-offs go to 5x4 at 73%: one more set and 3% more weight. This is the standard accumulation progression. Small, repeatable jumps let you pile up quality reps without a spike in fatigue. | G9: [ ]
A10: 2 | B10: Accumulation | C10: 2 | D10: Tuesday — Bench | E10: Bench press | F10: Bench goes to 7x4 at 73% of max, one more set and 3% more weight than Week 1. You should still finish each set with 2-3 reps in reserve. | G10: [ ]
A11: 2 | B11: Accumulation | C11: 3 | D11: Thursday — Deadlift | E11: Deadlift, 1.5-rep deadlift (knee height) | F11: Deadlift goes up to 72% but stays at 3 sets. Deadlift doesn't get an extra set here because each set costs so much recovery. The 1.5-rep deadlift adds its first 5 lb. Only take the jump if last week's reps were clean and RPE 7 or lower. | G11: [ ]
A12: 2 | B12: Accumulation | C12: 4 | D12: Friday — Bench variant / upper body | E12: Paused bench | F12: Paused bench replaces tempo bench as the lighter bench movement. It works a different skill (strength from a dead stop on the chest) at a similar easy weight, so this day doesn't get stale. | G12: [ ]
A13: 2 | B13: Accumulation | C13: 5 | D13: Saturday — Squat variant + Bent-over row | E13: Paused squat | F13: Paused squat moves to 3x5 at base + 5 lb, which is the highest-rep week of this lift. The bent-over row keeps its 4x4-6 structure. The weight only goes up if last week was clean. | G13: [ ]
A14: 3 | B14: Accumulation | C14: 1 | D14: Monday — Squat | E14: Squat — top single, Squat — back-off | F14: The top single goes to 87% of max and stays there through Week 4. The back-offs switch to 6x3 at 77%. Reps per set drop but total weight lifted keeps climbing, which is how accumulation builds work capacity without RPE spiking. | G14: [ ]
A15: 3 | B15: Accumulation | C15: 2 | D15: Tuesday — Bench | E15: Bench | F15: Bench stays at 7 sets but moves to 76% of max. RPE creeping to 7-8 is expected and fine. This is still submaximal work. | G15: [ ]
... A71: 13 | B71: Testing | C71: 8 | D71: Day 8 — Deadlift PR test | E71: Deadlift PR attempts | F71: Deadlift PR attempts, the last test of the program. Open around 90% of your current true 1RM and only increase attempts if the last one was clean. The three rest days beforehand mean this number reflects your actual strength, not leftover fatigue from the squat test. | G71: [ ]

Sheet Plate & Warm-up Reference
A1: CHIKO_LIFTS : PLATE LOADING & WARM-UP LADDER MATRIX
A2: Olympic Barbell Loading Breakdown (45 lb Bar) & Scientific Neural Warm-up Potentiation Ladders
A4: A. OLYMPIC BARBELL PLATE LOADING CHART (45 LB BAR) | H4: B. APP WARM-UP LADDER PROTOCOL
A5: Total Weight (lbs) | B5: Weight Per Side | C5: 45 lb Plates | D5: 35 & 25 lb Plates | E5: 10, 5 & 2.5 lb Plates | F5: Quick Load String | H5: Step | I5: Prescription Target | J5: Rep Scheme
A6: 95 | B6: 25 | C6: - | D6: 1x25 | E6: - | F6: 1x25 / side | H6: Step 1: Empty Bar | I6: 45 lbs | J6: 10 reps (Groove bar path)
A7: 115 | B7: 35 | C7: - | D7: 1x35 | E7: - | F7: 1x35 / side | H7: Step 2: 1st Jump | I7: Bench: 95-135 lbs / Squat & DL: 135-185 lbs | J7: 5 reps (Rhythm & bar speed)
A8: 135 | B8: 45 | C8: 1 plate(s) | D8: - | E8: - | F8: 1x45 / side | H8: Step 3: Moderate Load | I8: 40% - 60% of Target Working Weight | J8: 5 reps (Explosive intent)
A9: 155 | B9: 55 | C9: 1 plate(s) | D9: - | E9: 1x10 | F9: 1x45 + 1x10 / side | H9: Step 4: Potentiation | I9: 75% - 80% of Target Working Weight | J9: 3 reps (Zero grind)
A10: 175 | B10: 65 | C10: 1 plate(s) | D10: - | E10: 2x10 | F10: 1x45 + 2x10 / side | H10: Step 5: Primer Single | I10: 90% of Target Working Weight (if heavy) | J10: 1 rep (Crisp acclimation)
A11: 185 | B11: 70 | C11: 1 plate(s) | D11: 1x25 | E11: - | F11: 1x45 + 1x25 / side | H11: Working Sets | I11: Target Programmed Weight & RPE | J11: Prescribed Sets x Reps
A12: 205 | B12: 80 | C12: 1 plate(s) | D12: 1x35 | E12: - | F12: 1x45 + 1x35 / side
A13: 215 | B13: 85 | C13: 1 plate(s) | D13: 1x35 | E13: 1x5 | F13: 1x45 + 1x35 + 1x5 / side | H13: COACHING TIP: WARM-UP DISCIPLINE
A14: 225 | B14: 90 | C14: 2 plate(s) | D14: - | E14: - | F14: 2x45 / side | H14: • Warm-ups exist to grease the groove, potentiate high-threshold motor units, and test joint readiness. • Never take warm-ups to failure or accumulate lactic fatigue. • Keep rest periods brief on early sets (60s), extending to 2-3 minutes before the final primer single and first working set. • If bar speed feels sluggish during warm-ups, respect the 5% autoregulation drop rule on working sets.
A15: 245 | B15: 100 | C15: 2 plate(s) | D15: - | E15: 1x10 | F15: 2x45 + 1x10 / side
A16: 265 | B16: 110 | C16: 2 plate(s) | D16: - | E16: 2x10 | F16: 2x45 + 2x10 / side
A17: 275 | B17: 115 | C17: 2 plate(s) | D17: 1x25 | E17: - | F17: 2x45 + 1x25 / side
A18: 295 | B18: 125 | C18: 2 plate(s) | D18: 1x35 | E18: - | F18: 2x45 + 1x35 / side
A19: 305 | B19: 130 | C19: 2 plate(s) | D19: 1x35 | E19: 1x5 | F19: 2x45 + 1x35 + 1x5 / side
A20: 315 | B20: 135 | C20: 3 plate(s) | D20: - | E20: - | F20: 3x45 / side
A21: 335 | B21: 145 | C21: 3 plate(s) | D21: - | E21: 1x10 | F21: 3x45 + 1x10 / side
A22: 355 | B22: 155 | C22: 3 plate(s) | D22: - | E22: 2x10 | F22: 3x45 + 2x10 / side
A23: 365 | B23: 160 | C23: 3 plate(s) | D23: 1x25 | E23: - | F23: 3x45 + 1x25 / side
A24: 385 | B24: 170 | C24: 3 plate(s) | D24: 1x35 | E24: - | F24: 3x45 + 1x35 / side
A25: 405 | B25: 180 | C25: 4 plate(s) | D25: - | E25: - | F25: 4x45 / side
A26: 425 | B26: 190 | C26: 4 plate(s) | D26: - | E26: 1x10 | F26: 4x45 + 1x10 / side
... A35: 585 | B35: 270 | C35: 6 plate(s) | D35: - | E35: - | F35: 6x45 / side
